"will this catch block ever execute? so is it possible that we can go into the second error block?.given that we have some promise rejection or errors that happen in the logic section..somepromise.  .then(function(data) {.      //some logic.      return something;.    }).    .then((data) =&gt; {.      // more logic.    }, function(err) {.      // first error block.    }).    .catch(function(err) {.      // second error block.    });"
