"input() inside a function throws an exception->""input() takes 0 positional arguments but 1 was given"" def input():.    number = int(input('enter a number: ')).    return number..input()..def checkvalidity(val):.    if val == 0 and val &gt;= 2:.        switch(val).    else:.        input()..def switch(num):.    if num == 1:.        print('one').    elif num == 2:.        print('two').    else:.        print('null')..checkvalidity(number)...the input() works fine when defined without a function, but when defined in a function and called, it throws an exception."
