"getting an exception while running popen on a command i am running into the following error ,when running  popen on command as below,if i try the command manually it works,.am not sure what is wrong here?can anyone give pointers on what is wrong here?..error:-..traceback (most recent call last):.file ""test.py"", line 164, in main.buildpipe = popen(cmd, stdout=pipe, stderr=pipe).file ""/usr/lib/blank2.7/subprocess.py"", line 679, in __init__.errread, errwrite).file ""/usr/lib/blank2.7/subprocess.py"", line 1249, in _execute_child.raise child_exception.oserror: [errno 2] no such file or directory ...code:-..cmd = 'source build/envsetup.sh &amp;&amp; lunch %s-userdebug &amp;&amp; make -j32 2&gt;&amp;1 | tee build.log'% (target)..buildpipe = popen(cmd, stdout=pipe, stderr=pipe) .(output, error) = buildpipe.communicate()"
